Workbook

Sheet Orders by Status
A3: Row Labels | B3: Count of OrderID
A4: Cancelled | B4: 250
A5: Delivered | B5: 231
A6: Pending | B6: 237
A7: Returned | B7: 247
A8: Shipped | B8: 235
A9: Grand Total | B9: 1200

Sheet Revenue by Product
A3: Row Labels | B3: Sum of TotalPrice
A4: Chair | B4: 195620.11
A5: Desk | B5: 167459.93
A6: Laptop | B6: 192126.56
A7: Monitor | B7: 175651.41
A8: Phone | B8: 151722.39
A9: Printer | B9: 195612.61
A10: Tablet | B10: 186568.95
A11: Grand Total | B11: 1264762

Sheet Revenue by Referral Source
A3: Row Labels | B3: Sum of TotalPrice
A4: Email | B4: 261808.55
A5: Facebook | B5: 250410.9
A6: Google | B6: 250441.48
A7: Instagram | B7: 275285.45
A8: Referral | B8: 226815.58
A9: Grand Total | B9: 1264762

Sheet Average Order Value by Payment
A3: Row Labels | B3: Average of TotalPrice
A4: Cash | B4: 1056.0418
A5: Credit Card | B5: 1127.554
A6: Debit Card | B6: 1001.5568
A7: Gift Card | B7: 1070.9736
A8: Online | B8: 1017.2207
A9: Grand Total | B9: 1053.9683

Sheet Revenue by Month
A3: Row Labels | B3: Sum of TotalPrice
A4: 2023 | B4: 552643.24
A5: Jan | B5: 56685.75
A6: Feb | B6: 40117.66
A7: Mar | B7: 48609.37
A8: Apr | B8: 27751.71
A9: May | B9: 63836.84
A10: Jun | B10: 49500.19
A11: Jul | B11: 42820.66
A12: Aug | B12: 54352.14
A13: Sep | B13: 29526.67
A14: Oct | B14: 52607.85
A15: Nov | B15: 43079.67
... A37: Grand Total | B37: 1264762

Sheet EDA
A1: Quantity | C1: Unit Price | E1: Total Price | G1: Lower Bound | H1: =_xlfn.QUARTILE.INC('[1]Cleaned Data set'!N2:N1201,1)-1.5*(_xlfn.QUARTILE.INC('[1]Cleaned Data set'!N2:N1201,3)-_xlfn.QUARTILE.INC('[1]Cleaned Data set'!N2:N1201,1)) -> -1341.4125 | I1: Corr: Quantity vs UnitPrice | J1: =CORREL('[1]Cleaned Data set'!E2:E1201,'[1]Cleaned Data set'!F2:F1201) -> 0.014553341
G2: Upper Bound | H2: =_xlfn.QUARTILE.INC('[1]Cleaned Data set'!N2:N1201,3)+1.5*(_xlfn.QUARTILE.INC('[1]Cleaned Data set'!N2:N1201,3)-_xlfn.QUARTILE.INC('[1]Cleaned Data set'!N2:N1201,1)) -> 3330.4075 | I2: Corr: UnitPrice vs TotalPrice | J2: =CORREL('[1]Cleaned Data set'!F2:F1201,'[1]Cleaned Data set'!N2:N1201) -> 0.71708109
A3: Mean | B3: 2.9458333 | C3: Mean | D3: 356.41275 | E3: Mean | F3: 1053.9683 | I3: Corr: Quantity vs TotalPrice | J3: =CORREL('[1]Cleaned Data set'!E2:E1201,'[1]Cleaned Data set'!N2:N1201) -> 0.61525136
A4: Standard Error | B4: 0.040632673 | C4: Standard Error | D4: 5.6920139 | E4: Standard Error | F4: 23.66722
A5: Median | B5: 3 | C5: Median | D5: 364.21 | E5: Median | F5: 823.615
A6: Mode | B6: 1 | C6: Mode | D6: 127.18 | E6: Mode | F6: 635.9
A7: Standard Deviation | B7: 1.4075571 | C7: Standard Deviation | D7: 197.17715 | E7: Standard Deviation | F7: 819.85656
A8: Sample Variance | B8: 1.981217 | C8: Sample Variance | D8: 38878.827 | E8: Sample Variance | F8: 672164.78
A9: Kurtosis | B9: -1.2945959 | C9: Kurtosis | D9: -1.1910109 | E9: Kurtosis | F9: -0.040414717
A10: Skewness | B10: 0.027922314 | C10: Skewness | D10: -0.026511641 | E10: Skewness | F10: 0.89135908
A11: Range | B11: 4 | C11: Range | D11: 688.54 | E11: Range | F11: 3445.01
A12: Minimum | B12: 1 | C12: Minimum | D12: 11.39 | E12: Minimum | F12: 11.39
A13: Maximum | B13: 5 | C13: Maximum | D13: 699.93 | E13: Maximum | F13: 3456.4
A14: Sum | B14: 3535 | C14: Sum | D14: 427695.3 | E14: Sum | F14: 1264762
A15: Count | B15: 1200 | C15: Count | D15: 1200 | E15: Count | F15: 1200
A16: Confidence Level(95.0%) | B16: 0.07971905 | C16: Confidence Level(95.0%) | D16: 11.167415 | E16: Confidence Level(95.0%) | F16: 46.433772

Sheet Cleaned Data set
A1: OrderID | B1: Date | C1: CustomerID | D1: Product | E1: Quantity | F1: UnitPrice | G1: ShippingAddress | H1: PaymentMethod | I1: OrderStatus | J1: TrackingNumber | K1: ItemsInCart | L1: CouponCode | M1: ReferralSource | N1: TotalPrice | O1: CouponCode_Cleaned | P1: Outlier Flag
A2: ORD200000 | B2: 44930 | C2: C72649 | D2: Monitor | E2: 5 | F2: 570.62 | G2: 928 Main St | H2: Debit Card | I2: Shipped | J2: TRK37947903 | K2: 7 | L2: SAVE10 | M2: Instagram | N2: 2853.1 | O2: =IF(L2="","No Coupon",L2) -> SAVE10 | P2: =IF(OR(N2<EDA!$H$1,N2>EDA!$H$2),"Outlier","Normal") -> Normal
A3: ORD200001 | B3: 45527 | C3: C75739 | D3: Phone | E3: 2 | F3: 151.35 | G3: 823 Main St | H3: Online | I3: Shipped | J3: TRK91186779 | K3: 3 | L3: SAVE10 | M3: Referral | N3: 302.7 | O3: =IF(L3="","No Coupon",L3) -> SAVE10 | P3: =IF(OR(N3<EDA!$H$1,N3>EDA!$H$2),"Outlier","Normal") -> Normal
A4: ORD200002 | B4: 45349 | C4: C81728 | D4: Tablet | E4: 5 | F4: 550.68 | G4: 512 Main St | H4: Credit Card | I4: Cancelled | J4: TRK42903982 | K4: 8 | L4: FREESHIP | M4: Email | N4: 2753.4 | O4: =IF(L4="","No Coupon",L4) -> FREESHIP | P4: =IF(OR(N4<EDA!$H$1,N4>EDA!$H$2),"Outlier","Normal") -> Normal
A5: ORD200003 | B5: 45214 | C5: C33540 | D5: Chair | E5: 1 | F5: 273.19 | G5: 275 Main St | H5: Debit Card | I5: Returned | J5: TRK62788070 | K5: 5 | L5: SAVE10 | M5: Facebook | N5: 273.19 | O5: =IF(L5="","No Coupon",L5) -> SAVE10 | P5: =IF(OR(N5<EDA!$H$1,N5>EDA!$H$2),"Outlier","Normal") -> Normal
A6: ORD200004 | B6: 45785 | C6: C81840 | D6: Printer | E6: 4 | F6: 626.01 | G6: 668 Main St | H6: Online | I6: Delivered | J6: TRK29241424 | K6: 8 | L6: SAVE10 | M6: Email | N6: 2504.04 | O6: =IF(L6="","No Coupon",L6) -> SAVE10 | P6: =IF(OR(N6<EDA!$H$1,N6>EDA!$H$2),"Outlier","Normal") -> Normal
A7: ORD200005 | B7: 45222 | C7: C37249 | D7: Phone | E7: 2 | F7: 245.86 | G7: 934 Main St | H7: Credit Card | I7: Shipped | J7: TRK72976927 | K7: 4 | L7: SAVE10 | M7: Instagram | N7: 491.72 | O7: =IF(L7="","No Coupon",L7) -> SAVE10 | P7: =IF(OR(N7<EDA!$H$1,N7>EDA!$H$2),"Outlier","Normal") -> Normal
A8: ORD200006 | B8: 45825 | C8: C83492 | D8: Laptop | E8: 1 | F8: 664.42 | G8: 986 Main St | H8: Gift Card | I8: Returned | J8: TRK96417362 | K8: 6 | L8: SAVE10 | M8: Facebook | N8: 664.42 | O8: =IF(L8="","No Coupon",L8) -> SAVE10 | P8: =IF(OR(N8<EDA!$H$1,N8>EDA!$H$2),"Outlier","Normal") -> Normal
A9: ORD200007 | B9: 45058 | C9: C41460 | D9: Monitor | E9: 5 | F9: 149.55 | G9: 706 Main St | H9: Cash | I9: Shipped | J9: TRK78809193 | K9: 9 | L9: FREESHIP | M9: Facebook | N9: 747.75 | O9: =IF(L9="","No Coupon",L9) -> FREESHIP | P9: =IF(OR(N9<EDA!$H$1,N9>EDA!$H$2),"Outlier","Normal") -> Normal
A10: ORD200008 | B10: 45749 | C10: C26817 | D10: Phone | E10: 2 | F10: 134.28 | G10: 904 Main St | H10: Gift Card | I10: Cancelled | J10: TRK61042692 | K10: 2 | M10: Email | N10: 268.56 | O10: =IF(L10="","No Coupon",L10) -> No Coupon | P10: =IF(OR(N10<EDA!$H$1,N10>EDA!$H$2),"Outlier","Normal") -> Normal
A11: ORD200009 | B11: 45251 | C11: C31946 | D11: Desk | E11: 4 | F11: 509.38 | G11: 102 Main St | H11: Credit Card | I11: Shipped | J11: TRK33478363 | K11: 6 | L11: SAVE10 | M11: Google | N11: 2037.52 | O11: =IF(L11="","No Coupon",L11) -> SAVE10 | P11: =IF(OR(N11<EDA!$H$1,N11>EDA!$H$2),"Outlier","Normal") -> Normal
A12: ORD200010 | B12: 45289 | C12: C43443 | D12: Tablet | E12: 5 | F12: 625.97 | G12: 333 Main St | H12: Credit Card | I12: Returned | J12: TRK98859248 | K12: 9 | L12: WINTER15 | M12: Instagram | N12: 3129.85 | O12: =IF(L12="","No Coupon",L12) -> WINTER15 | P12: =IF(OR(N12<EDA!$H$1,N12>EDA!$H$2),"Outlier","Normal") -> Normal
A13: ORD200011 | B13: 45339 | C13: C93861 | D13: Monitor | E13: 3 | F13: 49.14 | G13: 831 Main St | H13: Online | I13: Returned | J13: TRK48234646 | K13: 7 | L13: SAVE10 | M13: Email | N13: 147.42 | O13: =IF(L13="","No Coupon",L13) -> SAVE10 | P13: =IF(OR(N13<EDA!$H$1,N13>EDA!$H$2),"Outlier","Normal") -> Normal
A14: ORD200012 | B14: 45580 | C14: C38785 | D14: Monitor | E14: 2 | F14: 180.5 | G14: 179 Main St | H14: Debit Card | I14: Pending | J14: TRK20419991 | K14: 6 | L14: FREESHIP | M14: Referral | N14: 361 | O14: =IF(L14="","No Coupon",L14) -> FREESHIP | P14: =IF(OR(N14<EDA!$H$1,N14>EDA!$H$2),"Outlier","Normal") -> Normal
A15: ORD200013 | B15: 45168 | C15: C88348 | D15: Laptop | E15: 3 | F15: 201.49 | G15: 903 Main St | H15: Credit Card | I15: Returned | J15: TRK81913874 | K15: 4 | L15: FREESHIP | M15: Facebook | N15: 604.47 | O15: =IF(L15="","No Coupon",L15) -> FREESHIP | P15: =IF(OR(N15<EDA!$H$1,N15>EDA!$H$2),"Outlier","Normal") -> Normal
A16: ORD200014 | B16: 45012 | C16: C98474 | D16: Tablet | E16: 2 | F16: 393.33 | G16: 980 Main St | H16: Debit Card | I16: Pending | J16: TRK79186539 | K16: 3 | L16: SAVE10 | M16: Instagram | N16: 786.66 | O16: =IF(L16="","No Coupon",L16) -> SAVE10 | P16: =IF(OR(N16<EDA!$H$1,N16>EDA!$H$2),"Outlier","Normal") -> Normal
A17: ORD200015 | B17: 45124 | C17: C39416 | D17: Printer | E17: 1 | F17: 473.96 | G17: 942 Main St | H17: Cash | I17: Delivered | J17: TRK54930938 | K17: 3 | M17: Google | N17: 473.96 | O17: =IF(L17="","No Coupon",L17) -> No Coupon | P17: =IF(OR(N17<EDA!$H$1,N17>EDA!$H$2),"Outlier","Normal") -> Normal
A18: ORD200016 | B18: 44950 | C18: C28976 | D18: Printer | E18: 2 | F18: 533.81 | G18: 914 Main St | H18: Credit Card | I18: Pending | J18: TRK13194259 | K18: 3 | L18: FREESHIP | M18: Email | N18: 1067.62 | O18: =IF(L18="","No Coupon",L18) -> FREESHIP | P18: =IF(OR(N18<EDA!$H$1,N18>EDA!$H$2),"Outlier","Normal") -> Normal
A19: ORD200017 | B19: 45353 | C19: C60672 | D19: Tablet | E19: 1 | F19: 423.4 | G19: 382 Main St | H19: Debit Card | I19: Shipped | J19: TRK11972116 | K19: 3 | M19: Referral | N19: 423.4 | O19: =IF(L19="","No Coupon",L19) -> No Coupon | P19: =IF(OR(N19<EDA!$H$1,N19>EDA!$H$2),"Outlier","Normal") -> Normal
A20: ORD200018 | B20: 45742 | C20: C84329 | D20: Desk | E20: 1 | F20: 431.44 | G20: 891 Main St | H20: Gift Card | I20: Pending | J20: TRK65191045 | K20: 3 | L20: SAVE10 | M20: Facebook | N20: 431.44 | O20: =IF(L20="","No Coupon",L20) -> SAVE10 | P20: =IF(OR(N20<EDA!$H$1,N20>EDA!$H$2),"Outlier","Normal") -> Normal
A21: ORD200019 | B21: 44949 | C21: C14552 | D21: Monitor | E21: 5 | F21: 224 | G21: 273 Main St | H21: Cash | I21: Returned | J21: TRK59101365 | K21: 9 | L21: SAVE10 | M21: Google | N21: 1120 | O21: =IF(L21="","No Coupon",L21) -> SAVE10 | P21: =IF(OR(N21<EDA!$H$1,N21>EDA!$H$2),"Outlier","Normal") -> Normal
A22: ORD200020 | B22: 45054 | C22: C54829 | D22: Chair | E22: 5 | F22: 62.51 | G22: 587 Main St | H22: Cash | I22: Pending | J22: TRK16718651 | K22: 9 | L22: WINTER15 | M22: Instagram | N22: 312.55 | O22: =IF(L22="","No Coupon",L22) -> WINTER15 | P22: =IF(OR(N22<EDA!$H$1,N22>EDA!$H$2),"Outlier","Normal") -> Normal
A23: ORD200021 | B23: 45613 | C23: C99023 | D23: Monitor | E23: 4 | F23: 342.95 | G23: 569 Main St | H23: Cash | I23: Delivered | J23: TRK52646983 | K23: 6 | M23: Google | N23: 1371.8 | O23: =IF(L23="","No Coupon",L23) -> No Coupon | P23: =IF(OR(N23<EDA!$H$1,N23>EDA!$H$2),"Outlier","Normal") -> Normal
A24: ORD200022 | B24: 44955 | C24: C34416 | D24: Monitor | E24: 2 | F24: 49.62 | G24: 633 Main St | H24: Online | I24: Pending | J24: TRK75937350 | K24: 2 | L24: SAVE10 | M24: Google | N24: 99.24 | O24: =IF(L24="","No Coupon",L24) -> SAVE10 | P24: =IF(OR(N24<EDA!$H$1,N24>EDA!$H$2),"Outlier","Normal") -> Normal
A25: ORD200023 | B25: 45756 | C25: C42372 | D25: Phone | E25: 4 | F25: 273.25 | G25: 755 Main St | H25: Debit Card | I25: Cancelled | J25: TRK36168083 | K25: 5 | L25: FREESHIP | M25: Referral | N25: 1093 | O25: =IF(L25="","No Coupon",L25) -> FREESHIP | P25: =IF(OR(N25<EDA!$H$1,N25>EDA!$H$2),"Outlier","Normal") -> Normal
A26: ORD200024 | B26: 45595 | C26: C17470 | D26: Laptop | E26: 2 | F26: 230.95 | G26: 956 Main St | H26: Online | I26: Delivered | J26: TRK28775057 | K26: 3 | L26: WINTER15 | M26: Referral | N26: 461.9 | O26: =IF(L26="","No Coupon",L26) -> WINTER15 | P26: =IF(OR(N26<EDA!$H$1,N26>EDA!$H$2),"Outlier","Normal") -> Normal
A27: ORD200025 | B27: 45497 | C27: C42577 | D27: Monitor | E27: 1 | F27: 399.98 | G27: 709 Main St | H27: Debit Card | I27: Delivered | J27: TRK69423327 | K27: 3 | L27: WINTER15 | M27: Email | N27: 399.98 | O27: =IF(L27="","No Coupon",L27) -> WINTER15 | P27: =IF(OR(N27<EDA!$H$1,N27>EDA!$H$2),"Outlier","Normal") -> Normal
A28: ORD200026 | B28: 45357 | C28: C21944 | D28: Laptop | E28: 5 | F28: 59.55 | G28: 296 Main St | H28: Online | I28: Delivered | J28: TRK80276812 | K28: 6 | M28: Referral | N28: 297.75 | O28: =IF(L28="","No Coupon",L28) -> No Coupon | P28: =IF(OR(N28<EDA!$H$1,N28>EDA!$H$2),"Outlier","Normal") -> Normal
A29: ORD200027 | B29: 45344 | C29: C97593 | D29: Printer | E29: 1 | F29: 472.74 | G29: 881 Main St | H29: Online | I29: Shipped | J29: TRK89117573 | K29: 6 | L29: WINTER15 | M29: Google | N29: 472.74 | O29: =IF(L29="","No Coupon",L29) -> WINTER15 | P29: =IF(OR(N29<EDA!$H$1,N29>EDA!$H$2),"Outlier","Normal") -> Normal
A30: ORD200028 | B30: 45251 | C30: C59823 | D30: Phone | E30: 4 | F30: 160.07 | G30: 568 Main St | H30: Online | I30: Pending | J30: TRK65895539 | K30: 5 | M30: Email | N30: 640.28 | O30: =IF(L30="","No Coupon",L30) -> No Coupon | P30: =IF(OR(N30<EDA!$H$1,N30>EDA!$H$2),"Outlier","Normal") -> Normal
A31: ORD200029 | B31: 45555 | C31: C33260 | D31: Desk | E31: 3 | F31: 423.53 | G31: 930 Main St | H31: Credit Card | I31: Delivered | J31: TRK59744090 | K31: 6 | L31: SAVE10 | M31: Referral | N31: 1270.59 | O31: =IF(L31="","No Coupon",L31) -> SAVE10 | P31: =IF(OR(N31<EDA!$H$1,N31>EDA!$H$2),"Outlier","Normal") -> Normal
A32: ORD200030 | B32: 45738 | C32: C44267 | D32: Monitor | E32: 2 | F32: 426.7 | G32: 895 Main St | H32: Online | I32: Pending | J32: TRK54751444 | K32: 5 | L32: SAVE10 | M32: Referral | N32: 853.4 | O32: =IF(L32="","No Coupon",L32) -> SAVE10 | P32: =IF(OR(N32<EDA!$H$1,N32>EDA!$H$2),"Outlier","Normal") -> Normal
A33: ORD200031 | B33: 45107 | C33: C26445 | D33: Chair | E33: 3 | F33: 500.08 | G33: 996 Main St | H33: Debit Card | I33: Returned | J33: TRK31229981 | K33: 6 | M33: Facebook | N33: 1500.24 | O33: =IF(L33="","No Coupon",L33) -> No Coupon | P33: =IF(OR(N33<EDA!$H$1,N33>EDA!$H$2),"Outlier","Normal") -> Normal
A34: ORD200032 | B34: 45047 | C34: C12388 | D34: Tablet | E34: 5 | F34: 536.72 | G34: 830 Main St | H34: Cash | I34: Delivered | J34: TRK99261395 | K34: 10 | M34: Email | N34: 2683.6 | O34: =IF(L34="","No Coupon",L34) -> No Coupon | P34: =IF(OR(N34<EDA!$H$1,N34>EDA!$H$2),"Outlier","Normal") -> Normal
A35: ORD200033 | B35: 45082 | C35: C52184 | D35: Chair | E35: 1 | F35: 162.77 | G35: 912 Main St | H35: Online | I35: Cancelled | J35: TRK73312471 | K35: 4 | L35: WINTER15 | M35: Facebook | N35: 162.77 | O35: =IF(L35="","No Coupon",L35) -> WINTER15 | P35: =IF(OR(N35<EDA!$H$1,N35>EDA!$H$2),"Outlier","Normal") -> Normal
A36: ORD200034 | B36: 44933 | C36: C67195 | D36: Chair | E36: 4 | F36: 576.52 | G36: 926 Main St | H36: Credit Card | I36: Pending | J36: TRK55467915 | K36: 5 | L36: WINTER15 | M36: Facebook | N36: 2306.08 | O36: =IF(L36="","No Coupon",L36) -> WINTER15 | P36: =IF(OR(N36<EDA!$H$1,N36>EDA!$H$2),"Outlier","Normal") -> Normal
A37: ORD200035 | B37: 45633 | C37: C50304 | D37: Monitor | E37: 2 | F37: 465.15 | G37: 128 Main St | H37: Online | I37: Shipped | J37: TRK46850888 | K37: 2 | L37: SAVE10 | M37: Facebook | N37: 930.3 | O37: =IF(L37="","No Coupon",L37) -> SAVE10 | P37: =IF(OR(N37<EDA!$H$1,N37>EDA!$H$2),"Outlier","Normal") -> Normal
A38: ORD200036 | B38: 45785 | C38: C59337 | D38: Laptop | E38: 2 | F38: 534.43 | G38: 465 Main St | H38: Debit Card | I38: Pending | J38: TRK50961250 | K38: 5 | M38: Facebook | N38: 1068.86 | O38: =IF(L38="","No Coupon",L38) -> No Coupon | P38: =IF(OR(N38<EDA!$H$1,N38>EDA!$H$2),"Outlier","Normal") -> Normal
A39: ORD200037 | B39: 45579 | C39: C10054 | D39: Laptop | E39: 2 | F39: 76.74 | G39: 409 Main St | H39: Cash | I39: Returned | J39: TRK94005261 | K39: 7 | L39: SAVE10 | M39: Instagram | N39: 153.48 | O39: =IF(L39="","No Coupon",L39) -> SAVE10 | P39: =IF(OR(N39<EDA!$H$1,N39>EDA!$H$2),"Outlier","Normal") -> Normal
A40: ORD200038 | B40: 45645 | C40: C15924 | D40: Laptop | E40: 1 | F40: 245.89 | G40: 549 Main St | H40: Debit Card | I40: Delivered | J40: TRK14835975 | K40: 3 | L40: SAVE10 | M40: Google | N40: 245.89 | O40: =IF(L40="","No Coupon",L40) -> SAVE10 | P40: =IF(OR(N40<EDA!$H$1,N40>EDA!$H$2),"Outlier","Normal") -> Normal
...
